#VRML_SIM R2021a utf8
WorldInfo {
  coordinateSystem "NUE"
}
Viewpoint {
  orientation -0.1815089959693606 0.9552954078425583 0.23337773702115375 1.837251669154081
  position 2.458376837315653 1.3239749306189976 -0.31880189035699535
}
TexturedBackground {
}
TexturedBackgroundLight {
}
RectangleArena {
  floorSize 15 15
}
Robot {
  translation 0.42208000026753806 -0.0002898814300370395 -0.22931492826210179
  rotation 0.03980897533893625 0.998862450676299 -0.02624976402564661 0.5998126246738495
  children [
    Transform {
      translation 0 0.0415 0
      children [
        Shape {
          appearance PBRAppearance {
            baseColor 0.0820075 0.364731 0.8
            roughness 1
            metalness 0
          }
          geometry DEF BODY Cylinder {
            height 0.08
            radius 0.045
          }
        }
      ]
    }
    HingeJoint {
      jointParameters HingeJointParameters {
        position 109.55920680497432
        axis -1 0 0
        anchor 0 0.025 0
      }
      device [
        RotationalMotor {
          name "left wheel motor"
          consumptionFactor 70
        }
        PositionSensor {
          name "left wheel sensor"
        }
      ]
      endPoint Solid {
        translation -0.045000000000000075 0.025 0
        rotation -1 0 0 4.04357189010094
        children [
          DEF WHEEL Transform {
            rotation 0 0 1 1.57
            children [
              Shape {
                appearance PBRAppearance {
                  baseColor 1 0 0
                  roughness 1
                  metalness 0
                }
                geometry Cylinder {
                  height 0.01
                  radius 0.025
                }
              }
            ]
          }
        ]
        name "left wheel"
        boundingObject USE WHEEL
        physics DEF PHYSICS_WHEEL Physics {
          density -1
          mass 0.05
        }
      }
    }
    HingeJoint {
      jointParameters HingeJointParameters {
        position 136.9472813055555
        axis -1 0 0
        anchor 0 0.025 0
      }
      device [
        RotationalMotor {
          name "right wheel motor"
          consumptionFactor 70
        }
        PositionSensor {
          name "right wheel sensor"
        }
      ]
      endPoint Solid {
        translation 0.045 0.025 0
        rotation 1 0 0 5.87014545239541
        children [
          USE WHEEL
        ]
        name "right wheel"
        boundingObject USE WHEEL
        physics USE PHYSICS_WHEEL
      }
    }
    Transform {
      translation 0.02 0.063 -0.0385
      rotation 0 1 0 2.7489
      children [
        DEF UNUSED_EYE Group {
          children [
            Transform {
              translation 0 0 -1e-05
              rotation 0 0 1 0.8
              children [
                Shape {
                  appearance PBRAppearance {
                    baseColor 0.975691 0.981481 0.0252992
                    roughness 1
                    metalness 0
                  }
                  geometry Box {
                    size 0.02 0.005 0.005
                  }
                }
              ]
            }
            Transform {
              rotation 0 0 1 -0.8
              children [
                Shape {
                  appearance PBRAppearance {
                    baseColor 0.975691 0.981481 0.0252992
                    roughness 1
                    metalness 0
                  }
                  geometry Box {
                    size 0.02 0.005 0.005
                  }
                }
              ]
            }
          ]
        }
      ]
    }
    Transform {
      translation -0.02 0.063 -0.0385
      rotation 0 1 0 0.3927
      children [
        USE UNUSED_EYE
      ]
    }
    DEF SMILE Transform {
      translation 0 0.025 -0.036
      rotation 0.7745972408364944 0.44721228048294853 0.4472139204829502 1.8234794
      children [
        Shape {
          appearance PBRAppearance {
            baseColor 0.721569 0.290196 0.290196
            roughness 1
            metalness 0
          }
          geometry Cylinder {
            height 0.018
            radius 0.009
            subdivision 3
          }
        }
      ]
    }
    Speaker {
      translation 0 0.085 0
      children [
        Shape {
          appearance PBRAppearance {
            baseColor 0.2 0.2 0.2
            baseColorMap ImageTexture {
              url [
                "textures/speaker.png"
              ]
            }
            roughness 0.5
            metalness 0
          }
          geometry Cylinder {
            height 0.01
            radius 0.03
            side FALSE
            subdivision 24
          }
        }
        Shape {
          appearance PBRAppearance {
            baseColor 0.2 0.2 0.2
            roughness 1
            metalness 0
          }
          geometry Cylinder {
            height 0.01
            radius 0.03
            top FALSE
            subdivision 24
          }
        }
      ]
    }
  ]
  name "mybot"
  boundingObject Transform {
    translation 0 0.0415 0
    children [
      USE BODY
    ]
  }
  physics Physics {
    density -1
    mass 0.5
  }
  controller "speaker"
}
